<mujoco model="template">
  <!-- This model has been converted from an OpenSim model. Model conversion by MyoConverter https://github.com/MyoHub/myoconverter. This model is licensed under Apache 2.0. -->
  <!-- Credits from the original OpenSim model. Note! If the following has any license information, it applies to the original OpenSim model. Credits: Delp S.L., Loan J.P., Hoy M.G., Zajac F.E., Topp E.L., Rosen J.M., Thelen D.G., Anderson F.C., Seth A., Hamner S.R. -->
  <!-- Note: inertiagrouprange="0 1" means that groups 0-1 will be used to infer masses/inertias, and groups 2-5 are
  only for visualisation (e.g. wrapping objects) !-->
  <compiler inertiafromgeom="auto" angle="radian" balanceinertia="true" boundmass="0.001" boundinertia="0.001" inertiagrouprange="0 1">
    <lengthrange inttotal="50" useexisting="true"/>
  </compiler>
  <option collision="predefined"/>
  <visual>
    <scale framelength="0.5" framewidth="0.01"/>
  </visual>
  <default>
    <joint limited="true" damping="0.05" armature="0.00001" stiffness="0"/>
    <geom rgba="0.8 0.6 .4 1" margin="0.001"/>
    <site size="0.001"/>
    <tendon width="0.005" rgba=".95 .3 .3 1" limited="false"/>
    <default class="muscle">
      <muscle ctrllimited="true" ctrlrange="0 1" scale="200"/>
    </default>
    <default class="motor">
      <general gainprm="5 0 0 0 0 0 0 0 0 0"/>
    </default>
  </default>
  <option timestep="0.002"/>
  <!-- nuser_jnt=1, the parameter is used to store default value of the joint, and nkey=1 to store keyframe with
   default joint positions set !-->
  <size njmax="1000" nconmax="400" nuser_jnt="1" nkey="1"/>
  <worldbody>
    <!-- The converter script assumes a body named 'ground' exists as a child element of worldbody -->
    <body name="ground" euler="1.571 0 0">
      <geom name="ground-plane" pos="0 0 0" euler="-1.571 0 0" size="10 10 0.125" type="plane" rgba="1.0 0.7 0.4 1.0" condim="3"/>
    </body>
    <light directional="true"/>
    <body name="pelvis" pos="0 0 1" euler="1.571 0 0">
      <inertial mass="9.0705373802730396" pos="-0.072539130981511116 0 0" fullinertia="0.083348411321942012 0.07061913060448588 0.046944290034440103 0 0 0"/>
      <geom name="pelvis_geom_0" type="mesh" mesh="pelvis_geom_0_sacrum" rgba="1 1 1 1" group="0"/>
      <geom name="pelvis_geom_1" type="mesh" mesh="pelvis_geom_1_pelvis" rgba="1 1 1 1" group="0"/>
      <geom name="pelvis_geom_2" type="mesh" mesh="pelvis_geom_2_l_pelvis" rgba="1 1 1 1" group="0"/>
      <joint name="pelvis_tx" range="-5 5" limited="true" user="0.0" ref="0" axis="1 0 0" type="slide" damping="0" stiffness="0"/>
      <joint name="pelvis_ty" range="-1 2" limited="true" user="0.0" ref="0" axis="0 0 -1" type="slide" damping="0" stiffness="0"/>
      <joint name="pelvis_tz" range="-3 3" limited="true" user="0.0" ref="0" axis="0 1 0" type="slide" damping="0" stiffness="0"/>
      <!-- <joint name="pelvis_tilt" range="-1.571 1.571" limited="true" user="0.0" ref="0" axis="0 0 1" type="hinge" damping="0" stiffness="0"/>
      <joint name="pelvis_list" range="-1.571 1.571" limited="true" user="0.0" ref="0" axis="1 0 0" type="hinge" damping="0" stiffness="0"/>
      <joint name="pelvis_rotation" range="-1.571 1.571" limited="true" user="0.0" ref="0" axis="0 1 0" type="hinge" damping="0" stiffness="0"/> -->
      <joint name="pelvis" type="ball" pos="0 0 0"/>
      <body name="femur_r" pos="-0.07254 -0.06782 0.08567" euler="-0 0 0">
        <inertial mass="8.3552437887027367" pos="0 -0.18360000000000001 0" fullinertia="0.14029393381142954 0.036776079736976677 0.14794252019547313 0 0 0"/>
        <geom name="femur_r_geom_0" type="mesh" mesh="femur_r_geom_0_femur_r" rgba="1 1 1 1" group="0"/>
        <!-- <joint name="hip_flexion_r" range="-2.094 2.094" limited="true" user="0.0" ref="0" axis="0 0 1" type="hinge"/>
        <joint name="hip_adduction_r" range="-2.094 2.094" limited="true" user="0.0" ref="0" axis="1 0 0" type="hinge"/>
        <joint name="hip_rotation_r" range="-2.094 2.094" limited="true" user="0.0" ref="0" axis="0 1 0" type="hinge"/> -->
        <joint name="hip_r" type="ball" pos="0 0 0"/>
        <body name="tibia_r" pos="0 -0.4269 0" euler="-0 0 0">
          <inertial mass="3.060473302634529" pos="0 -0.19603500000000001 0" fullinertia="0.045868714641723603 0.0046414770768410793 0.04650578012285865 0 0 0"/>
          <geom name="tibia_r_geom_0" type="mesh" mesh="tibia_r_geom_0_tibia_r" rgba="1 1 1 1" group="0"/>
          <geom name="tibia_r_geom_1" type="mesh" mesh="tibia_r_geom_1_fibula_r" rgba="1 1 1 1" group="0"/>
          <!-- <joint name="knee_r_translation1" range="-0.00602 0.004439" limited="true"  ref="0" axis="1 0 0" type="slide"/> -->
          <!-- <joint name="knee_r_translation2" range="-0.4564 -0.4269" limited="true"  ref="0" axis="0 1 0" type="slide"/> -->
          <!-- <joint name="knee_angle_r" range="-2.094 0.1745" limited="true" user="0.0" ref="0" axis="0 0 1" type="hinge"/> -->
          <joint name="knee_r" type="ball" pos="0 0 0"/>
          <body name="talus_r" pos="0 -0.4515 0" euler="-0 0 0">
            <inertial mass="0.064052220263485532" pos="0 0 0" fullinertia="0.00059629882706858245 0.00059629882706858245 0.00059629882706858245 0 0 0"/>
            <geom name="talus_r_geom_0" type="mesh" mesh="talus_r_geom_0_talus_rv" rgba="1 1 1 1" group="0"/>
            <!-- <joint name="ankle_angle_r" range="-1.571 1.571" limited="true" user="0.0" ref="0" axis="-0.105 -0.174 0.9791" type="hinge"/> -->
            <joint name="ankle_r" type="ball" pos="0 0 0"/>
            <body name="calcn_r" pos="-0.04706 -0.04048 0.007642" euler="-0 0 0">
              <inertial mass="0.8246655796265977" pos="0.097441233318256479 0.029232369995476942 0" fullinertia="0.00087696333274956621 0.0024429692840880774 0.0025682497601951584 0 0 0"/>
              <geom name="calcn_r_geom_0" type="mesh" mesh="calcn_r_geom_0_foot" rgba="1 1 1 1" group="0"/>
              <!-- <joint name="subtalar_angle_r" range="-1.571 1.571" limited="true" user="0.0" ref="0" axis="0.7872 0.6047 -0.1209" type="hinge"/> -->
              <body name="toes_r" pos="0.1742 -0.001949 0.001052" euler="-0 0 0">
                <inertial mass="0.12937990705270636" pos="0.032616126297600884 0.0056559756585435059 -0.016496595670751891" fullinertia="5.307878159321047e-05 0.00010615756318642094 0.00053078781593210466 0 0 0"/>
                <geom name="toes_r_geom_0" type="mesh" mesh="toes_r_geom_0_bofoot" rgba="1 1 1 1" group="0"/>
                <!-- <joint name="mtp_angle_r" range="-1.571 1.571" limited="true" user="0.0" ref="0" axis="-0.581 0 0.8139" type="hinge"/> -->
              </body>
            </body>
          </body>
        </body>
      </body>
      <body name="femur_l" pos="-0.07254 -0.06782 -0.08567" euler="-0 0 0">
        <inertial mass="8.3552437887027367" pos="0 -0.18360000000000001 0" fullinertia="0.14029393381142954 0.036776079736976677 0.14794252019547313 0 0 0"/>
        <geom name="femur_l_geom_0" type="mesh" mesh="femur_l_geom_0_femur_l" rgba="1 1 1 1" group="0"/>
        <!-- <joint name="hip_flexion_l" range="-2.094 2.094" limited="true" user="0.0" ref="0" axis="0 0 1" type="hinge"/>
        <joint name="hip_adduction_l" range="-2.094 2.094" limited="true" user="0.0" ref="0" axis="-1 0 0" type="hinge"/>
        <joint name="hip_rotation_l" range="-2.094 2.094" limited="true" user="0.0" ref="0" axis="0 -1 0" type="hinge"/> -->
        <joint name="hip_l" type="ball" pos="0 0 0"/>
        <body name="tibia_l" pos="0 -0.4269 0" euler="-0 0 0">
          <inertial mass="3.060473302634529" pos="0 -0.19603500000000001 0" fullinertia="0.045868714641723603 0.0046414770768410793 0.04650578012285865 0 0 0"/>
          <geom name="tibia_l_geom_0" type="mesh" mesh="tibia_l_geom_0_tibia_l" rgba="1 1 1 1" group="0"/>
          <geom name="tibia_l_geom_1" type="mesh" mesh="tibia_l_geom_1_fibula_l" rgba="1 1 1 1" group="0"/>
          <!-- <joint name="knee_l_translation1" range="-0.00602 0.004439" limited="true" user="-0.003930386360834814" ref="0" axis="1 0 0" type="slide"/> -->
          <!-- <joint name="knee_l_translation2" range="-0.4564 -0.4269" limited="true" user="-0.42737052074859855" ref="0" axis="0 1 0" type="slide"/> -->
          <!-- <joint name="knee_angle_l" range="-2.094 0.1745" limited="true" user="0.0" ref="0" axis="0 0 1" type="hinge"/> -->
          <joint name="knee_l" type="ball" pos="0 0 0"/>
          <body name="talus_l" pos="0 -0.4515 0" euler="-0 0 0">
            <inertial mass="0.062311729825197115" pos="0 0 0" fullinertia="0.00056953880631792993 0.00056953880631792993 0.00056953880631792993 0 0 0"/>
            <geom name="talus_l_geom_0" type="mesh" mesh="talus_l_geom_0_talus_lv" rgba="1 1 1 1" group="0"/>
            <!-- <joint name="ankle_angle_l" range="-1.047 1.047" limited="true" user="0.0" ref="0" axis="0.105 0.174 0.9791" type="hinge"/> -->
            <joint name="ankle_l" type="ball" pos="0 0 0"/>
            <body name="calcn_l" pos="-0.04663 -0.04011 -0.007572" euler="-0 0 0">
              <inertial mass="0.77889662281496386" pos="0.095604152605071033 0.028681245781521307 0" fullinertia="0.00079735432884510198 0.0022212013446399267 0.0023351091059035131 0 0 0"/>
              <geom name="calcn_l_geom_0" type="mesh" mesh="calcn_l_geom_0_l_foot" rgba="1 1 1 1" group="0"/>
              <!-- <joint name="subtalar_angle_l" range="-1.571 1.571" limited="true" user="0.0" ref="0" axis="-0.7872 -0.6047 -0.1209" type="hinge"/> -->
              <body name="toes_l" pos="0.1709 -0.001912 -0.001033" euler="-0 0 0">
                <inertial mass="0.12117616099993421" pos="0.031911643014741496 0.0055338109274118211 0.016140281871617812" fullinertia="4.7588812692207461e-05 9.5177625384414922e-05 0.00047588812692207462 0 0 0"/>
                <geom name="toes_l_geom_0" type="mesh" mesh="toes_l_geom_0_l_bofoot" rgba="1 1 1 1" group="0"/>
                <!-- <joint name="mtp_angle_l" range="-1.047 1.047" limited="true" user="0.0" ref="0" axis="0.581 0 0.8139" type="hinge"/> -->
              </body>
            </body>
          </body>
        </body>
      </body>
      <body name="torso" pos="-0.1033 0.08362 0" euler="-0 0 0">
        <inertial mass="29.439730577709447" pos="-0.034636245377956142 0.36945328403153221 0" fullinertia="2.1569102798830069 1.1051513845043144 2.0938632584771351 0 0 0"/>
        <geom name="torso_geom_0" type="mesh" mesh="torso_geom_0_hat_spine" rgba="1 1 1 1" group="0"/>
        <geom name="torso_geom_1" type="mesh" mesh="torso_geom_1_hat_jaw" rgba="1 1 1 1" group="0"/>
        <geom name="torso_geom_2" type="mesh" mesh="torso_geom_2_hat_skull" rgba="1 1 1 1" group="0"/>
        <geom name="torso_geom_3" type="mesh" mesh="torso_geom_3_hat_ribs_scap" rgba="1 1 1 1" group="0"/>
        <!-- <joint name="lumbar_extension" range="-1.571 1.571" limited="true" user="0.0" ref="0" axis="0 0 1" type="hinge"/>
        <joint name="lumbar_bending" range="-1.571 1.571" limited="true" user="0.0" ref="0" axis="1 0 0" type="hinge"/>
        <joint name="lumbar_rotation" range="-1.571 1.571" limited="true" user="0.0" ref="0" axis="0 1 0" type="hinge"/> -->
        <joint name="lumbar" type="ball" pos="0 0 0"/>
        <body name="humerus_r" pos="0.003643 0.4289 0.1963" euler="-0 0 0">
          <inertial mass="1.2364191758484753" pos="0 -0.15601621186407807 0" fullinertia="0.0065366432173699415 0.0022549394524344151 0.0073371713462006974 0 0 0"/>
          <geom name="humerus_r_geom_0" type="mesh" mesh="humerus_r_geom_0_humerus_rv" rgba="1 1 1 1" group="0"/>
          <!-- <joint name="arm_flex_r" range="-1.571 1.571" limited="true" user="0.0" ref="0" axis="0 0 1" type="hinge"/>
          <joint name="arm_add_r" range="-2.094 1.571" limited="true" user="0.0" ref="0" axis="1 0 0" type="hinge"/>
          <joint name="arm_rot_r" range="-1.571 1.571" limited="true" user="0.0" ref="0" axis="0 1 0" type="hinge"/> -->
          <joint name="arm_r" type="ball" pos="0 0 0"/>
          <body name="ulna_r" pos="0.01247 -0.2715 -0.0091" euler="-0 0 0">
            <inertial mass="0.45097295643487201" pos="0 -0.12215147053874564 0" fullinertia="0.0022585639411456799 0.00047123312479001707 0.0024499547410199427 0 0 0"/>
            <geom name="ulna_r_geom_0" type="mesh" mesh="ulna_r_geom_0_ulna_rv" rgba="1 1 1 1" group="0"/>
            <!-- <joint name="elbow_flex_r" range="0 2.618" limited="true" user="0.0" ref="0" axis="0.226 0.02227 0.9739" type="hinge"/> -->
            <joint name="elbow_r" type="ball" pos="0 0 0"/>
            <body name="radius_r" pos="-0.006818 -0.01318 0.02643" euler="-0 0 0">
              <inertial mass="0.45097295643487201" pos="0 -0.12215147053874564 0" fullinertia="0.0022585639411456799 0.00047123312479001707 0.0024499547410199427 0 0 0"/>
              <geom name="radius_r_geom_0" type="mesh" mesh="radius_r_geom_0_radius_rv" rgba="1 1 1 1" group="0"/>
              <joint name="pro_sup_r" range="0 1.571" limited="true" user="0.0" ref="0" axis="0.0564 0.9984 0.001952" type="hinge"/>
              <body name="hand_r" pos="-0.008916 -0.239 0.01379" euler="-0 0 0">
                <inertial mass="0.32623506351011716" pos="0 -0.068095000000000003 0" fullinertia="0.00063606923858147441 0.00039005591200007452 0.00095553002208427767 0 0 0"/>
                <geom name="hand_r_geom_0" type="mesh" mesh="hand_r_geom_0_pisiform_rvs" rgba="1 1 1 1" group="0"/>
                <geom name="hand_r_geom_1" type="mesh" mesh="hand_r_geom_1_lunate_rvs" rgba="1 1 1 1" group="0"/>
                <geom name="hand_r_geom_2" type="mesh" mesh="hand_r_geom_2_scaphoid_rvs" rgba="1 1 1 1" group="0"/>
                <geom name="hand_r_geom_3" type="mesh" mesh="hand_r_geom_3_triquetrum_rvs" rgba="1 1 1 1" group="0"/>
                <geom name="hand_r_geom_4" type="mesh" mesh="hand_r_geom_4_hamate_rvs" rgba="1 1 1 1" group="0"/>
                <geom name="hand_r_geom_5" type="mesh" mesh="hand_r_geom_5_capitate_rvs" rgba="1 1 1 1" group="0"/>
                <geom name="hand_r_geom_6" type="mesh" mesh="hand_r_geom_6_trapezoid_rvs" rgba="1 1 1 1" group="0"/>
                <geom name="hand_r_geom_7" type="mesh" mesh="hand_r_geom_7_trapezium_rvs" rgba="1 1 1 1" group="0"/>
                <geom name="hand_r_geom_8" type="mesh" mesh="hand_r_geom_8_metacarpal2_rvs" rgba="1 1 1 1" group="0"/>
                <geom name="hand_r_geom_9" type="mesh" mesh="hand_r_geom_9_index_proximal_rvs" rgba="1 1 1 1" group="0"/>
                <geom name="hand_r_geom_10" type="mesh" mesh="hand_r_geom_10_index_medial_rvs" rgba="1 1 1 1" group="0"/>
                <geom name="hand_r_geom_11" type="mesh" mesh="hand_r_geom_11_index_distal_rvs" rgba="1 1 1 1" group="0"/>
                <geom name="hand_r_geom_12" type="mesh" mesh="hand_r_geom_12_metacarpal3_rvs" rgba="1 1 1 1" group="0"/>
                <geom name="hand_r_geom_13" type="mesh" mesh="hand_r_geom_13_middle_proximal_rvs" rgba="1 1 1 1" group="0"/>
                <geom name="hand_r_geom_14" type="mesh" mesh="hand_r_geom_14_middle_medial_rvs" rgba="1 1 1 1" group="0"/>
                <geom name="hand_r_geom_15" type="mesh" mesh="hand_r_geom_15_middle_distal_rvs" rgba="1 1 1 1" group="0"/>
                <geom name="hand_r_geom_16" type="mesh" mesh="hand_r_geom_16_metacarpal4_rvs" rgba="1 1 1 1" group="0"/>
                <geom name="hand_r_geom_17" type="mesh" mesh="hand_r_geom_17_ring_proximal_rvs" rgba="1 1 1 1" group="0"/>
                <geom name="hand_r_geom_18" type="mesh" mesh="hand_r_geom_18_ring_medial_rvs" rgba="1 1 1 1" group="0"/>
                <geom name="hand_r_geom_19" type="mesh" mesh="hand_r_geom_19_ring_distal_rvs" rgba="1 1 1 1" group="0"/>
                <geom name="hand_r_geom_20" type="mesh" mesh="hand_r_geom_20_metacarpal5_rvs" rgba="1 1 1 1" group="0"/>
                <geom name="hand_r_geom_21" type="mesh" mesh="hand_r_geom_21_little_proximal_rvs" rgba="1 1 1 1" group="0"/>
                <geom name="hand_r_geom_22" type="mesh" mesh="hand_r_geom_22_little_medial_rvs" rgba="1 1 1 1" group="0"/>
                <geom name="hand_r_geom_23" type="mesh" mesh="hand_r_geom_23_little_distal_rvs" rgba="1 1 1 1" group="0"/>
                <geom name="hand_r_geom_24" type="mesh" mesh="hand_r_geom_24_metacarpal1_rvs" rgba="1 1 1 1" group="0"/>
                <geom name="hand_r_geom_25" type="mesh" mesh="hand_r_geom_25_thumb_proximal_rvs" rgba="1 1 1 1" group="0"/>
                <geom name="hand_r_geom_26" type="mesh" mesh="hand_r_geom_26_thumb_distal_rvs" rgba="1 1 1 1" group="0"/>
                <!-- <joint name="wrist_flex_r" range="-1.222 1.222" limited="true" user="0.0" ref="0" axis="0 0 1" type="hinge"/>
                <joint name="wrist_dev_r" range="-0.4363 0.6109" limited="true" user="0.0" ref="0" axis="1 0 0" type="hinge"/> -->
              </body>
            </body>
          </body>
        </body>
        <body name="humerus_l" pos="0.003643 0.4289 -0.1963" euler="-0 0 0">
          <inertial mass="1.4394147125327033" pos="0 -0.16412565185414793 0" fullinertia="0.0084214806793569841 0.0029051499982948371 0.0094528406520590826 0 0 0"/>
          <geom name="humerus_l_geom_0" type="mesh" mesh="humerus_l_geom_0_humerus_lv" rgba="1 1 1 1" group="0"/>
          <!-- <joint name="arm_flex_l" range="-1.571 1.571" limited="true" user="0.0" ref="0" axis="0 0 1" type="hinge"/>
          <joint name="arm_add_l" range="-2.094 1.571" limited="true" user="0.0" ref="0" axis="-1 0 0" type="hinge"/>
          <joint name="arm_rot_l" range="-1.571 1.571" limited="true" user="0.0" ref="0" axis="0 -1 0" type="hinge"/> -->
          <joint name="arm_l" type="ball" pos="0 0 0"/>
          <body name="ulna_l" pos="0.01311 -0.2856 0.009573" euler="-0 0 0">
            <inertial mass="0.47378285524446129" pos="0 -0.12417713821185419 0" fullinertia="0.0024521505274575535 0.0005116235739259853 0.0026599458624986905 0 0 0"/>
            <geom name="ulna_l_geom_0" type="mesh" mesh="ulna_l_geom_0_ulna_lv" rgba="1 1 1 1" group="0"/>
            <!-- <joint name="elbow_flex_l" range="0 2.618" limited="true" user="0.0" ref="0" axis="-0.226 -0.02227 0.9739" type="hinge"/> -->
            <joint name="elbow_l" type="ball" pos="0 0 0"/>
            <body name="radius_l" pos="-0.006931 -0.0134 -0.02687" euler="-0 0 0">
              <inertial mass="0.47378285524446129" pos="0 -0.12417713821185419 0" fullinertia="0.0024521505274575535 0.0005116235739259853 0.0026599458624986905 0 0 0"/>
              <geom name="radius_l_geom_0" type="mesh" mesh="radius_l_geom_0_radius_lv" rgba="1 1 1 1" group="0"/>
              <joint name="pro_sup_l" range="0 1.571" limited="true" user="0.0" ref="0" axis="-0.0564 -0.9984 0.001952" type="hinge"/>
              <body name="hand_l" pos="-0.009064 -0.243 -0.01402" euler="-0 0 0">
                <inertial mass="0.32623506351011716" pos="0 -0.068095000000000003 0" fullinertia="0.00063606923858147441 0.00039005591200007452 0.00095553002208427767 0 0 0"/>
                <geom name="hand_l_geom_0" type="mesh" mesh="hand_l_geom_0_pisiform_lvs" rgba="1 1 1 1" group="0"/>
                <geom name="hand_l_geom_1" type="mesh" mesh="hand_l_geom_1_lunate_lvs" rgba="1 1 1 1" group="0"/>
                <geom name="hand_l_geom_2" type="mesh" mesh="hand_l_geom_2_scaphoid_lvs" rgba="1 1 1 1" group="0"/>
                <geom name="hand_l_geom_3" type="mesh" mesh="hand_l_geom_3_triquetrum_lvs" rgba="1 1 1 1" group="0"/>
                <geom name="hand_l_geom_4" type="mesh" mesh="hand_l_geom_4_hamate_lvs" rgba="1 1 1 1" group="0"/>
                <geom name="hand_l_geom_5" type="mesh" mesh="hand_l_geom_5_capitate_lvs" rgba="1 1 1 1" group="0"/>
                <geom name="hand_l_geom_6" type="mesh" mesh="hand_l_geom_6_trapezoid_lvs" rgba="1 1 1 1" group="0"/>
                <geom name="hand_l_geom_7" type="mesh" mesh="hand_l_geom_7_trapezium_lvs" rgba="1 1 1 1" group="0"/>
                <geom name="hand_l_geom_8" type="mesh" mesh="hand_l_geom_8_metacarpal2_lvs" rgba="1 1 1 1" group="0"/>
                <geom name="hand_l_geom_9" type="mesh" mesh="hand_l_geom_9_index_proximal_lvs" rgba="1 1 1 1" group="0"/>
                <geom name="hand_l_geom_10" type="mesh" mesh="hand_l_geom_10_index_medial_lvs" rgba="1 1 1 1" group="0"/>
                <geom name="hand_l_geom_11" type="mesh" mesh="hand_l_geom_11_index_distal_lvs" rgba="1 1 1 1" group="0"/>
                <geom name="hand_l_geom_12" type="mesh" mesh="hand_l_geom_12_metacarpal3_lvs" rgba="1 1 1 1" group="0"/>
                <geom name="hand_l_geom_13" type="mesh" mesh="hand_l_geom_13_middle_proximal_lvs" rgba="1 1 1 1" group="0"/>
                <geom name="hand_l_geom_14" type="mesh" mesh="hand_l_geom_14_middle_medial_lvs" rgba="1 1 1 1" group="0"/>
                <geom name="hand_l_geom_15" type="mesh" mesh="hand_l_geom_15_middle_distal_lvs" rgba="1 1 1 1" group="0"/>
                <geom name="hand_l_geom_16" type="mesh" mesh="hand_l_geom_16_metacarpal4_lvs" rgba="1 1 1 1" group="0"/>
                <geom name="hand_l_geom_17" type="mesh" mesh="hand_l_geom_17_ring_proximal_lvs" rgba="1 1 1 1" group="0"/>
                <geom name="hand_l_geom_18" type="mesh" mesh="hand_l_geom_18_ring_medial_lvs" rgba="1 1 1 1" group="0"/>
                <geom name="hand_l_geom_19" type="mesh" mesh="hand_l_geom_19_ring_distal_lvs" rgba="1 1 1 1" group="0"/>
                <geom name="hand_l_geom_20" type="mesh" mesh="hand_l_geom_20_metacarpal5_lvs" rgba="1 1 1 1" group="0"/>
                <geom name="hand_l_geom_21" type="mesh" mesh="hand_l_geom_21_little_proximal_lvs" rgba="1 1 1 1" group="0"/>
                <geom name="hand_l_geom_22" type="mesh" mesh="hand_l_geom_22_little_medial_lvs" rgba="1 1 1 1" group="0"/>
                <geom name="hand_l_geom_23" type="mesh" mesh="hand_l_geom_23_little_distal_lvs" rgba="1 1 1 1" group="0"/>
                <geom name="hand_l_geom_24" type="mesh" mesh="hand_l_geom_24_metacarpal1_lvs" rgba="1 1 1 1" group="0"/>
                <geom name="hand_l_geom_25" type="mesh" mesh="hand_l_geom_25_thumb_proximal_lvs" rgba="1 1 1 1" group="0"/>
                <geom name="hand_l_geom_26" type="mesh" mesh="hand_l_geom_26_thumb_distal_lvs" rgba="1 1 1 1" group="0"/>
                <!-- <joint name="wrist_flex_l" range="-1.222 1.222" limited="true" user="0.0" ref="0" axis="0 0 1" type="hinge"/>
                <joint name="wrist_dev_l" range="-0.4363 0.6109" limited="true" user="0.0" ref="0" axis="-1 0 0" type="hinge"/> -->
              </body>
            </body>
          </body>
        </body>
      </body>
    </body>
  </worldbody>
  <asset>
    <texture type="skybox" builtin="gradient" rgb1="1 1 1" rgb2="0.6 0.8 1" width="256" height="256"/>
    <mesh name="pelvis_geom_0_sacrum" file="Geometry/sacrum.stl" scale="1.0260131680553199 1.0260131680553199 1.0260131680553199"/>
    <mesh name="pelvis_geom_1_pelvis" file="Geometry/pelvis.stl" scale="1.0260131680553199 1.0260131680553199 1.0260131680553199"/>
    <mesh name="pelvis_geom_2_l_pelvis" file="Geometry/l_pelvis.stl" scale="1.0260131680553199 1.0260131680553199 1.0260131680553199"/>
    <mesh name="femur_r_geom_0_femur_r" file="Geometry/femur_r.stl" scale="1.0800000000000001 1.0800000000000001 1.0800000000000001"/>
    <mesh name="tibia_r_geom_0_tibia_r" file="Geometry/tibia_r.stl" scale="1.05 1.05 1.05"/>
    <mesh name="tibia_r_geom_1_fibula_r" file="Geometry/fibula_r.stl" scale="1.05 1.05 1.05"/>
    <mesh name="talus_r_geom_0_talus_rv" file="Geometry/talus_rv.stl" scale="0.96486129079853955 0.96486129079853955 0.96486129079853955"/>
    <mesh name="calcn_r_geom_0_foot" file="Geometry/foot.stl" scale="0.9744123331825647 0.9744123331825647 0.9744123331825647"/>
    <mesh name="toes_r_geom_0_bofoot" file="Geometry/bofoot.stl" scale="0.94266260975725091 0.94266260975725091 0.94266260975725091"/>
    <mesh name="femur_l_geom_0_femur_l" file="Geometry/femur_l.stl" scale="1.0800000000000001 1.0800000000000001 1.0800000000000001"/>
    <mesh name="tibia_l_geom_0_tibia_l" file="Geometry/tibia_l.stl" scale="1.05 1.05 1.05"/>
    <mesh name="tibia_l_geom_1_fibula_l" file="Geometry/fibula_l.stl" scale="1.05 1.05 1.05"/>
    <mesh name="talus_l_geom_0_talus_lv" file="Geometry/talus_lv.stl" scale="0.95604152605071024 0.95604152605071024 0.95604152605071024"/>
    <mesh name="calcn_l_geom_0_l_foot" file="Geometry/l_foot.stl" scale="0.95604152605071024 0.95604152605071024 0.95604152605071024"/>
    <mesh name="toes_l_geom_0_l_bofoot" file="Geometry/l_bofoot.stl" scale="0.92230182123530347 0.92230182123530347 0.92230182123530347"/>
    <mesh name="torso_geom_0_hat_spine" file="Geometry/hat_spine.stl" scale="1.1545415125985381 1.1545415125985381 1.1545415125985381"/>
    <mesh name="torso_geom_1_hat_jaw" file="Geometry/hat_jaw.stl" scale="1.1545415125985381 1.1545415125985381 1.1545415125985381"/>
    <mesh name="torso_geom_2_hat_skull" file="Geometry/hat_skull.stl" scale="1.1545415125985381 1.1545415125985381 1.1545415125985381"/>
    <mesh name="torso_geom_3_hat_ribs_scap" file="Geometry/hat_ribs_scap.stl" scale="1.1545415125985381 1.1545415125985381 1.1545415125985381"/>
    <mesh name="humerus_r_geom_0_humerus_rv" file="Geometry/humerus_rv.stl" scale="0.94841528895744776 0.94841528895744776 0.94841528895744776"/>
    <mesh name="ulna_r_geom_0_ulna_rv" file="Geometry/ulna_rv.stl" scale="1.0134948810516129 1.0134948810516129 1.0134948810516129"/>
    <mesh name="radius_r_geom_0_radius_rv" file="Geometry/radius_rv.stl" scale="1.0134948810516129 1.0134948810516129 1.0134948810516129"/>
    <mesh name="hand_r_geom_0_pisiform_rvs" file="Geometry/pisiform_rvs.stl" scale="0.84999999999999998 0.84999999999999998 0.84999999999999998"/>
    <mesh name="hand_r_geom_1_lunate_rvs" file="Geometry/lunate_rvs.stl" scale="0.84999999999999998 0.84999999999999998 0.84999999999999998"/>
    <mesh name="hand_r_geom_2_scaphoid_rvs" file="Geometry/scaphoid_rvs.stl" scale="0.84999999999999998 0.84999999999999998 0.84999999999999998"/>
    <mesh name="hand_r_geom_3_triquetrum_rvs" file="Geometry/triquetrum_rvs.stl" scale="0.84999999999999998 0.84999999999999998 0.84999999999999998"/>
    <mesh name="hand_r_geom_4_hamate_rvs" file="Geometry/hamate_rvs.stl" scale="0.84999999999999998 0.84999999999999998 0.84999999999999998"/>
    <mesh name="hand_r_geom_5_capitate_rvs" file="Geometry/capitate_rvs.stl" scale="0.84999999999999998 0.84999999999999998 0.84999999999999998"/>
    <mesh name="hand_r_geom_6_trapezoid_rvs" file="Geometry/trapezoid_rvs.stl" scale="0.84999999999999998 0.84999999999999998 0.84999999999999998"/>
    <mesh name="hand_r_geom_7_trapezium_rvs" file="Geometry/trapezium_rvs.stl" scale="0.84999999999999998 0.84999999999999998 0.84999999999999998"/>
    <mesh name="hand_r_geom_8_metacarpal2_rvs" file="Geometry/metacarpal2_rvs.stl" scale="0.84999999999999998 0.84999999999999998 0.84999999999999998"/>
    <mesh name="hand_r_geom_9_index_proximal_rvs" file="Geometry/index_proximal_rvs.stl" scale="0.84999999999999998 0.84999999999999998 0.84999999999999998"/>
    <mesh name="hand_r_geom_10_index_medial_rvs" file="Geometry/index_medial_rvs.stl" scale="0.84999999999999998 0.84999999999999998 0.84999999999999998"/>
    <mesh name="hand_r_geom_11_index_distal_rvs" file="Geometry/index_distal_rvs.stl" scale="0.84999999999999998 0.84999999999999998 0.84999999999999998"/>
    <mesh name="hand_r_geom_12_metacarpal3_rvs" file="Geometry/metacarpal3_rvs.stl" scale="0.84999999999999998 0.84999999999999998 0.84999999999999998"/>
    <mesh name="hand_r_geom_13_middle_proximal_rvs" file="Geometry/middle_proximal_rvs.stl" scale="0.84999999999999998 0.84999999999999998 0.84999999999999998"/>
    <mesh name="hand_r_geom_14_middle_medial_rvs" file="Geometry/middle_medial_rvs.stl" scale="0.84999999999999998 0.84999999999999998 0.84999999999999998"/>
    <mesh name="hand_r_geom_15_middle_distal_rvs" file="Geometry/middle_distal_rvs.stl" scale="0.84999999999999998 0.84999999999999998 0.84999999999999998"/>
    <mesh name="hand_r_geom_16_metacarpal4_rvs" file="Geometry/metacarpal4_rvs.stl" scale="0.84999999999999998 0.84999999999999998 0.84999999999999998"/>
    <mesh name="hand_r_geom_17_ring_proximal_rvs" file="Geometry/ring_proximal_rvs.stl" scale="0.84999999999999998 0.84999999999999998 0.84999999999999998"/>
    <mesh name="hand_r_geom_18_ring_medial_rvs" file="Geometry/ring_medial_rvs.stl" scale="0.84999999999999998 0.84999999999999998 0.84999999999999998"/>
    <mesh name="hand_r_geom_19_ring_distal_rvs" file="Geometry/ring_distal_rvs.stl" scale="0.84999999999999998 0.84999999999999998 0.84999999999999998"/>
    <mesh name="hand_r_geom_20_metacarpal5_rvs" file="Geometry/metacarpal5_rvs.stl" scale="0.84999999999999998 0.84999999999999998 0.84999999999999998"/>
    <mesh name="hand_r_geom_21_little_proximal_rvs" file="Geometry/little_proximal_rvs.stl" scale="0.84999999999999998 0.84999999999999998 0.84999999999999998"/>
    <mesh name="hand_r_geom_22_little_medial_rvs" file="Geometry/little_medial_rvs.stl" scale="0.84999999999999998 0.84999999999999998 0.84999999999999998"/>
    <mesh name="hand_r_geom_23_little_distal_rvs" file="Geometry/little_distal_rvs.stl" scale="0.84999999999999998 0.84999999999999998 0.84999999999999998"/>
    <mesh name="hand_r_geom_24_metacarpal1_rvs" file="Geometry/metacarpal1_rvs.stl" scale="0.84999999999999998 0.84999999999999998 0.84999999999999998"/>
    <mesh name="hand_r_geom_25_thumb_proximal_rvs" file="Geometry/thumb_proximal_rvs.stl" scale="0.84999999999999998 0.84999999999999998 0.84999999999999998"/>
    <mesh name="hand_r_geom_26_thumb_distal_rvs" file="Geometry/thumb_distal_rvs.stl" scale="0.84999999999999998 0.84999999999999998 0.84999999999999998"/>
    <mesh name="humerus_l_geom_0_humerus_lv" file="Geometry/humerus_lv.stl" scale="0.9977121971413595 0.9977121971413595 0.9977121971413595"/>
    <mesh name="ulna_l_geom_0_ulna_lv" file="Geometry/ulna_lv.stl" scale="1.0303019142240548 1.0303019142240548 1.0303019142240548"/>
    <mesh name="radius_l_geom_0_radius_lv" file="Geometry/radius_lv.stl" scale="1.0303019142240548 1.0303019142240548 1.0303019142240548"/>
    <mesh name="hand_l_geom_0_pisiform_lvs" file="Geometry/pisiform_lvs.stl" scale="0.84999999999999998 0.84999999999999998 0.84999999999999998"/>
    <mesh name="hand_l_geom_1_lunate_lvs" file="Geometry/lunate_lvs.stl" scale="0.84999999999999998 0.84999999999999998 0.84999999999999998"/>
    <mesh name="hand_l_geom_2_scaphoid_lvs" file="Geometry/scaphoid_lvs.stl" scale="0.84999999999999998 0.84999999999999998 0.84999999999999998"/>
    <mesh name="hand_l_geom_3_triquetrum_lvs" file="Geometry/triquetrum_lvs.stl" scale="0.84999999999999998 0.84999999999999998 0.84999999999999998"/>
    <mesh name="hand_l_geom_4_hamate_lvs" file="Geometry/hamate_lvs.stl" scale="0.84999999999999998 0.84999999999999998 0.84999999999999998"/>
    <mesh name="hand_l_geom_5_capitate_lvs" file="Geometry/capitate_lvs.stl" scale="0.84999999999999998 0.84999999999999998 0.84999999999999998"/>
    <mesh name="hand_l_geom_6_trapezoid_lvs" file="Geometry/trapezoid_lvs.stl" scale="0.84999999999999998 0.84999999999999998 0.84999999999999998"/>
    <mesh name="hand_l_geom_7_trapezium_lvs" file="Geometry/trapezium_lvs.stl" scale="0.84999999999999998 0.84999999999999998 0.84999999999999998"/>
    <mesh name="hand_l_geom_8_metacarpal2_lvs" file="Geometry/metacarpal2_lvs.stl" scale="0.84999999999999998 0.84999999999999998 0.84999999999999998"/>
    <mesh name="hand_l_geom_9_index_proximal_lvs" file="Geometry/index_proximal_lvs.stl" scale="0.84999999999999998 0.84999999999999998 0.84999999999999998"/>
    <mesh name="hand_l_geom_10_index_medial_lvs" file="Geometry/index_medial_lvs.stl" scale="0.84999999999999998 0.84999999999999998 0.84999999999999998"/>
    <mesh name="hand_l_geom_11_index_distal_lvs" file="Geometry/index_distal_lvs.stl" scale="0.84999999999999998 0.84999999999999998 0.84999999999999998"/>
    <mesh name="hand_l_geom_12_metacarpal3_lvs" file="Geometry/metacarpal3_lvs.stl" scale="0.84999999999999998 0.84999999999999998 0.84999999999999998"/>
    <mesh name="hand_l_geom_13_middle_proximal_lvs" file="Geometry/middle_proximal_lvs.stl" scale="0.84999999999999998 0.84999999999999998 0.84999999999999998"/>
    <mesh name="hand_l_geom_14_middle_medial_lvs" file="Geometry/middle_medial_lvs.stl" scale="0.84999999999999998 0.84999999999999998 0.84999999999999998"/>
    <mesh name="hand_l_geom_15_middle_distal_lvs" file="Geometry/middle_distal_lvs.stl" scale="0.84999999999999998 0.84999999999999998 0.84999999999999998"/>
    <mesh name="hand_l_geom_16_metacarpal4_lvs" file="Geometry/metacarpal4_lvs.stl" scale="0.84999999999999998 0.84999999999999998 0.84999999999999998"/>
    <mesh name="hand_l_geom_17_ring_proximal_lvs" file="Geometry/ring_proximal_lvs.stl" scale="0.84999999999999998 0.84999999999999998 0.84999999999999998"/>
    <mesh name="hand_l_geom_18_ring_medial_lvs" file="Geometry/ring_medial_lvs.stl" scale="0.84999999999999998 0.84999999999999998 0.84999999999999998"/>
    <mesh name="hand_l_geom_19_ring_distal_lvs" file="Geometry/ring_distal_lvs.stl" scale="0.84999999999999998 0.84999999999999998 0.84999999999999998"/>
    <mesh name="hand_l_geom_20_metacarpal5_lvs" file="Geometry/metacarpal5_lvs.stl" scale="0.84999999999999998 0.84999999999999998 0.84999999999999998"/>
    <mesh name="hand_l_geom_21_little_proximal_lvs" file="Geometry/little_proximal_lvs.stl" scale="0.84999999999999998 0.84999999999999998 0.84999999999999998"/>
    <mesh name="hand_l_geom_22_little_medial_lvs" file="Geometry/little_medial_lvs.stl" scale="0.84999999999999998 0.84999999999999998 0.84999999999999998"/>
    <mesh name="hand_l_geom_23_little_distal_lvs" file="Geometry/little_distal_lvs.stl" scale="0.84999999999999998 0.84999999999999998 0.84999999999999998"/>
    <mesh name="hand_l_geom_24_metacarpal1_lvs" file="Geometry/metacarpal1_lvs.stl" scale="0.84999999999999998 0.84999999999999998 0.84999999999999998"/>
    <mesh name="hand_l_geom_25_thumb_proximal_lvs" file="Geometry/thumb_proximal_lvs.stl" scale="0.84999999999999998 0.84999999999999998 0.84999999999999998"/>
    <mesh name="hand_l_geom_26_thumb_distal_lvs" file="Geometry/thumb_distal_lvs.stl" scale="0.84999999999999998 0.84999999999999998 0.84999999999999998"/>
  </asset>
  <tendon>
    <!-- Leave this comment here to make 'tendon' element pretty printed !-->
  </tendon>
  <actuator>
    <!-- Leave this comment here to make 'actuator' element pretty printed !-->
  </actuator>
  <equality>
    <!-- Leave this comment here to make 'equality' element pretty printed !-->
    <!-- <joint joint1="knee_r_translation1" joint2="knee_angle_r" polycoef="-0.00393 -0.006768 0.003031 0.001448 -0.0007318" solimp="0.9999 0.9999 0.001 0.5 2" active="true"/>
    <joint joint1="knee_r_translation2" joint2="knee_angle_r" polycoef="-0.4274 0.003687 -0.006033 0.0007232 0.0006128" solimp="0.9999 0.9999 0.001 0.5 2" active="true"/> -->
    <!-- <joint name="subtalar_angle_r_locked" active="true" joint1="subtalar_angle_r" polycoef="0.0 0 0 0 0" solimp="0.9999 0.9999 0.001 0.5 2"/>
    <joint name="mtp_angle_r_locked" active="true" joint1="mtp_angle_r" polycoef="0.0 0 0 0 0" solimp="0.9999 0.9999 0.001 0.5 2"/> -->
    <!-- <joint joint1="knee_l_translation1" joint2="knee_angle_l" polycoef="-0.00393 -0.006768 0.003031 0.001448 -0.0007318" solimp="0.9999 0.9999 0.001 0.5 2" active="true"/>
    <joint joint1="knee_l_translation2" joint2="knee_angle_l" polycoef="-0.4274 0.003687 -0.006033 0.0007232 0.0006128" solimp="0.9999 0.9999 0.001 0.5 2" active="true"/> -->
    <!-- <joint name="subtalar_angle_l_locked" active="true" joint1="subtalar_angle_l" polycoef="0.0 0 0 0 0" solimp="0.9999 0.9999 0.001 0.5 2"/>
    <joint name="mtp_angle_l_locked" active="true" joint1="mtp_angle_l" polycoef="0.0 0 0 0 0" solimp="0.9999 0.9999 0.001 0.5 2"/> -->
    <!-- <joint name="wrist_flex_r_locked" active="true" joint1="wrist_flex_r" polycoef="0.0 0 0 0 0" solimp="0.9999 0.9999 0.001 0.5 2"/>
    <joint name="wrist_dev_r_locked" active="true" joint1="wrist_dev_r" polycoef="0.0 0 0 0 0" solimp="0.9999 0.9999 0.001 0.5 2"/>
    <joint name="wrist_flex_l_locked" active="true" joint1="wrist_flex_l" polycoef="0.0 0 0 0 0" solimp="0.9999 0.9999 0.001 0.5 2"/>
    <joint name="wrist_dev_l_locked" active="true" joint1="wrist_dev_l" polycoef="0.0 0 0 0 0" solimp="0.9999 0.9999 0.001 0.5 2"/> -->
  </equality>
  <contact>
    <!-- Leave this comment here to make 'contact' element pretty printed !-->
    <pair geom1="ground-plane" geom2="pelvis_geom_0"/>
    <pair geom1="ground-plane" geom2="pelvis_geom_1"/>
    <pair geom1="ground-plane" geom2="pelvis_geom_2"/>
    <pair geom1="ground-plane" geom2="femur_r_geom_0"/>
    <pair geom1="ground-plane" geom2="tibia_r_geom_0"/>
    <pair geom1="ground-plane" geom2="tibia_r_geom_1"/>
    <pair geom1="ground-plane" geom2="talus_r_geom_0"/>
    <pair geom1="ground-plane" geom2="calcn_r_geom_0"/>
    <pair geom1="ground-plane" geom2="toes_r_geom_0"/>
    <pair geom1="ground-plane" geom2="femur_l_geom_0"/>
    <pair geom1="ground-plane" geom2="tibia_l_geom_0"/>
    <pair geom1="ground-plane" geom2="tibia_l_geom_1"/>
    <pair geom1="ground-plane" geom2="talus_l_geom_0"/>
    <pair geom1="ground-plane" geom2="calcn_l_geom_0"/>
    <pair geom1="ground-plane" geom2="toes_l_geom_0"/>
    <pair geom1="ground-plane" geom2="torso_geom_0"/>
    <pair geom1="ground-plane" geom2="torso_geom_1"/>
    <pair geom1="ground-plane" geom2="torso_geom_2"/>
    <pair geom1="ground-plane" geom2="torso_geom_3"/>
    <pair geom1="ground-plane" geom2="humerus_r_geom_0"/>
    <pair geom1="ground-plane" geom2="ulna_r_geom_0"/>
    <pair geom1="ground-plane" geom2="radius_r_geom_0"/>
    <pair geom1="ground-plane" geom2="hand_r_geom_0"/>
    <pair geom1="ground-plane" geom2="hand_r_geom_1"/>
    <pair geom1="ground-plane" geom2="hand_r_geom_2"/>
    <pair geom1="ground-plane" geom2="hand_r_geom_3"/>
    <pair geom1="ground-plane" geom2="hand_r_geom_4"/>
    <pair geom1="ground-plane" geom2="hand_r_geom_5"/>
    <pair geom1="ground-plane" geom2="hand_r_geom_6"/>
    <pair geom1="ground-plane" geom2="hand_r_geom_7"/>
    <pair geom1="ground-plane" geom2="hand_r_geom_8"/>
    <pair geom1="ground-plane" geom2="hand_r_geom_9"/>
    <pair geom1="ground-plane" geom2="hand_r_geom_10"/>
    <pair geom1="ground-plane" geom2="hand_r_geom_11"/>
    <pair geom1="ground-plane" geom2="hand_r_geom_12"/>
    <pair geom1="ground-plane" geom2="hand_r_geom_13"/>
    <pair geom1="ground-plane" geom2="hand_r_geom_14"/>
    <pair geom1="ground-plane" geom2="hand_r_geom_15"/>
    <pair geom1="ground-plane" geom2="hand_r_geom_16"/>
    <pair geom1="ground-plane" geom2="hand_r_geom_17"/>
    <pair geom1="ground-plane" geom2="hand_r_geom_18"/>
    <pair geom1="ground-plane" geom2="hand_r_geom_19"/>
    <pair geom1="ground-plane" geom2="hand_r_geom_20"/>
    <pair geom1="ground-plane" geom2="hand_r_geom_21"/>
    <pair geom1="ground-plane" geom2="hand_r_geom_22"/>
    <pair geom1="ground-plane" geom2="hand_r_geom_23"/>
    <pair geom1="ground-plane" geom2="hand_r_geom_24"/>
    <pair geom1="ground-plane" geom2="hand_r_geom_25"/>
    <pair geom1="ground-plane" geom2="hand_r_geom_26"/>
    <pair geom1="ground-plane" geom2="humerus_l_geom_0"/>
    <pair geom1="ground-plane" geom2="ulna_l_geom_0"/>
    <pair geom1="ground-plane" geom2="radius_l_geom_0"/>
    <pair geom1="ground-plane" geom2="hand_l_geom_0"/>
    <pair geom1="ground-plane" geom2="hand_l_geom_1"/>
    <pair geom1="ground-plane" geom2="hand_l_geom_2"/>
    <pair geom1="ground-plane" geom2="hand_l_geom_3"/>
    <pair geom1="ground-plane" geom2="hand_l_geom_4"/>
    <pair geom1="ground-plane" geom2="hand_l_geom_5"/>
    <pair geom1="ground-plane" geom2="hand_l_geom_6"/>
    <pair geom1="ground-plane" geom2="hand_l_geom_7"/>
    <pair geom1="ground-plane" geom2="hand_l_geom_8"/>
    <pair geom1="ground-plane" geom2="hand_l_geom_9"/>
    <pair geom1="ground-plane" geom2="hand_l_geom_10"/>
    <pair geom1="ground-plane" geom2="hand_l_geom_11"/>
    <pair geom1="ground-plane" geom2="hand_l_geom_12"/>
    <pair geom1="ground-plane" geom2="hand_l_geom_13"/>
    <pair geom1="ground-plane" geom2="hand_l_geom_14"/>
    <pair geom1="ground-plane" geom2="hand_l_geom_15"/>
    <pair geom1="ground-plane" geom2="hand_l_geom_16"/>
    <pair geom1="ground-plane" geom2="hand_l_geom_17"/>
    <pair geom1="ground-plane" geom2="hand_l_geom_18"/>
    <pair geom1="ground-plane" geom2="hand_l_geom_19"/>
    <pair geom1="ground-plane" geom2="hand_l_geom_20"/>
    <pair geom1="ground-plane" geom2="hand_l_geom_21"/>
    <pair geom1="ground-plane" geom2="hand_l_geom_22"/>
    <pair geom1="ground-plane" geom2="hand_l_geom_23"/>
    <pair geom1="ground-plane" geom2="hand_l_geom_24"/>
    <pair geom1="ground-plane" geom2="hand_l_geom_25"/>
    <pair geom1="ground-plane" geom2="hand_l_geom_26"/>
  </contact>
  <!-- <keyframe>
    <key name="default-pose" qpos="0 0 0 0 0 0 0 0 0 -0.00393 -0.4274 0 0 0 0 0 0 0 -0.00393 -0.4274 0 0 0 0 0 0 0 0 0 0 0 0 0 0 0 0 0 0 0 0 0"/>
  </keyframe> -->
</mujoco>
